<?xml version="1.0" encoding="UTF-8"?>
<!-- Generated by org.testng.reporters.JUnitReportReporter -->
<testsuite hostname="DESKTOP-2GB3AA6" failures="0" tests="6" name="com.learn.retryfailedtest.RetryFailedTestDemo" time="0.034" errors="1" timestamp="2024-05-18T13:59:57 IST" skipped="3">
  <testcase classname="com.learn.retryfailedtest.RetryFailedTestDemo" name="test1" time="0.015"/>
  <testcase classname="com.learn.retryfailedtest.RetryFailedTestDemo" name="test2" time="0.002">
    <error message="/ by zero" type="java.lang.ArithmeticException">
      <![CDATA[java.lang.ArithmeticException: / by zero
at com.learn.retryfailedtest.RetryFailedTestDemo.test2(RetryFailedTestDemo.java:18)
at java.base/jdk.internal.reflect.NativeMethodAccessorImpl.invoke0(Native Method)
at java.base/jdk.internal.reflect.NativeMethodAccessorImpl.invoke(NativeMethodAccessorImpl.java:77)
at java.base/jdk.internal.reflect.DelegatingMethodAccessorImpl.invoke(DelegatingMethodAccessorImpl.java:43)
at java.base/java.lang.reflect.Method.invoke(Method.java:568)
at org.testng.internal.invokers.MethodInvocationHelper.invokeMethod(MethodInvocationHelper.java:139)
at org.testng.internal.invokers.TestInvoker.invokeMethod(TestInvoker.java:664)
at org.testng.internal.invokers.TestInvoker.retryFailed(TestInvoker.java:249)
at org.testng.internal.invokers.MethodRunner.runInSequence(MethodRunner.java:76)
at org.testng.internal.invokers.TestInvoker$MethodInvocationAgent.invoke(TestInvoker.java:961)
at org.testng.internal.invokers.TestInvoker.invokeTestMethods(TestInvoker.java:201)
at org.testng.internal.invokers.TestMethodWorker.invokeTestMethods(TestMethodWorker.java:148)
at org.testng.internal.invokers.TestMethodWorker.run(TestMethodWorker.java:128)
at java.base/java.util.ArrayList.forEach(ArrayList.java:1511)
at org.testng.TestRunner.privateRun(TestRunner.java:819)
at org.testng.TestRunner.run(TestRunner.java:619)
at org.testng.SuiteRunner.runTest(SuiteRunner.java:443)
at org.testng.SuiteRunner.runSequentially(SuiteRunner.java:437)
at org.testng.SuiteRunner.privateRun(SuiteRunner.java:397)
at org.testng.SuiteRunner.run(SuiteRunner.java:336)
at org.testng.SuiteRunnerWorker.runSuite(SuiteRunnerWorker.java:52)
at org.testng.SuiteRunnerWorker.run(SuiteRunnerWorker.java:95)
at org.testng.TestNG.runSuitesSequentially(TestNG.java:1301)
at org.testng.TestNG.runSuitesLocally(TestNG.java:1228)
at org.testng.TestNG.runSuites(TestNG.java:1134)
at org.testng.TestNG.run(TestNG.java:1101)
at org.testng.remote.AbstractRemoteTestNG.run(AbstractRemoteTestNG.java:115)
at org.testng.remote.RemoteTestNG.initAndRun(RemoteTestNG.java:293)
at org.testng.remote.RemoteTestNG.main(RemoteTestNG.java:91)
]]>
    </error>
  </testcase> <!-- test2 -->
  <testcase classname="com.learn.retryfailedtest.RetryFailedTestDemo" name="test2" time="0.005">
    <skipped/>
  </testcase> <!-- test2 -->
  <testcase classname="com.learn.retryfailedtest.RetryFailedTestDemo" name="test2" time="0.003">
    <skipped/>
  </testcase> <!-- test2 -->
  <testcase classname="com.learn.retryfailedtest.RetryFailedTestDemo" name="test3" time="0.005"/>
  <testcase classname="com.learn.retryfailedtest.RetryFailedTestDemo" name="test2" time="0.004">
    <skipped/>
  </testcase> <!-- test2 -->
</testsuite> <!-- com.learn.retryfailedtest.RetryFailedTestDemo -->
